Workbook

Sheet Start
A1: Owner Builder in a Box: Owner Workbook
A2: Your whole owner-build in one spreadsheet. Works offline in Excel, Numbers, LibreOffice or Google Sheets (offline mode).
A3: Includes Guides and common Q&A for tracking your project efficiently
A4: How it works
A5: Colours | B5: White cells are for you. Grey cells are calculated and locked so they can't be typed over by accident (Review > Unprotect sheet if you need to; there's no password). Pale yellow rows are examples: delete them when you're ready (the Dashboard counts what's left).
A6: Start here | B6: 1. Fill in the Project tab. 2. Set your budgets on Packages. 3. Work through Compliance and Gateways from G0. 4. Log everything else as it happens.
A7: Files | B7: Documents live in Google Drive, not in the workbook. Register each one on the Documents tab: it builds a Doc ID (e.g. 02-DWG-012), the file name to use, and the Drive folder to save it in. Paste the Drive link once it's uploaded. Share documents, photos and tender documents with trades and others as needed. (recommend to use suggested naming conventions for files)
A8: Offline | B8: Excel / Numbers / LibreOffice: open this file and work. With Google Drive / Dropbox / Onedrive for desktop the project folder is on your computer too, so you can save files offline and they sync later. Google Sheets: turn on Drive > Settings > Offline, or in the Sheets app tap ⋮ > Make available offline. The Apps Script menu needs a connection.
A9: Folder links | B9: The Open links work with Google Drive, Dropbox, OneDrive or SharePoint: paste each folder's link (Share > Copy link) into the Google Drive Map tab. Working offline on a computer, paste the local folder path instead and it opens without internet.
A10: Google Sheets fast set-up | B10: Upload this file to Drive, open it, then File > Save as Google Sheets. Then Extensions > Apps Script, paste in Code.gs, save and reload. A new Owner Builder menu appears: Set up Drive folders creates the folder tree for this build and links every folder path in the workbook.
A11: Need more rows? | B11: Each tab has room for hundreds of entries. If you run out, unprotect the sheet and copy the last row down so the formulas come too. The Dashboard warns if anything is typed below the last formula row.
A12: Tabs
A13: Dashboard | B13: Current gateway, money, compliance progress and everything that needs attention.
A14: Project | B14: Address, title, owners, budget, permits, site classification.
A15: Guides / Q&A / Reference | B15: Buying guides, plain-English answers and key numbers from Owner Builder in a Box. Read-only.
A16: Gate Review | B16: G0 to G7: progress against entry, deliverables and exit checks, with your Go / Hold / Stop decision.
A17: Gateways | B17: Every entry criterion, deliverable and exit check for each gate.
A18: Compliance | B18: The 11-stage Victorian owner-builder checklist, with the folder to file the evidence in.
A19: Risks | B19: Starter risk register with likelihood × impact ratings.
A20: Google Drive Map | B20: The folder tree, what goes in each folder, the file naming rules, and the folder links.
A21: Rooms | B21: Room sizes give floor area, paint area, skirting length and tile quantities. Area type keeps garages and outdoor areas out of the paint and skirting figures.
A22: Selections | B22: Every product decision: spec, supplier, price, status.
A23: Diary | B23: Site diary, plan notes, instructions to trades, defects, questions for the building surveyor.
A24: Photos | B24: Log of site photos, especially before anything is covered.
... A31: Settings | B31: The legal thresholds and rules behind the checks (deposit caps, contract, warranty and consent thresholds, warning days). Update them here when the law changes.
A32: Important
A33: Not advice | B33: General information only. It is not legal, financial or building advice. Always confirm current requirements with the Building and Plumbing Commission (BPC), your relevant building surveyor, your council and WorkSafe Victoria. Victorian rules checked September 2026.

Sheet Dashboard
A1: Dashboard
A2: Where the build is up to. Everything here is calculated; change the other tabs, not this one.
A4: Project
A5: Project | B5: =IF(Project!$B$5="","(name it on the Project tab)",Project!$B$5)
A6: Current gateway | B6: =Project!$B$12&" "&IFERROR(INDEX('Gate Review'!$B$4:$B$11,MATCH(Project!$B$12,'Gate Review'!$A$4:$A$11,0)),"")
A7: Exit checks done at this gate | B7: =IFERROR(INDEX('Gate Review'!$H$4:$H$11,MATCH(Project!$B$12,'Gate Review'!$A$4:$A$11,0)),"")
A8: Ready to pass? | B8: =IFERROR(INDEX('Gate Review'!$I$4:$I$11,MATCH(Project!$B$12,'Gate Review'!$A$4:$A$11,0)),"")
A10: Money
A11: Total budget | B11: =N(Project!$B$16)
A12: Contingency in the budget | B12: =B11*N(Project!$B$17)
A13: Allocated to packages | B13: =SUM('Packages'!$H$4:$H$33) | F13: Sum of Packages budgets. Should be about the total budget less contingency.
A14: Committed (contracts + approved variations) | B14: =SUM('Packages'!$K$4:$K$33)
A15: Committed as % of package budgets | B15: =IF(B13=0,"",B14/B13) | F15: G3 exit check: compare with the target on Settings before going to site.
A16: G3 target | B16: =Settings!$B$14
A17: Spent to date (paid) | B17: =SUMIFS('Payments'!$F$4:$F$303,'Payments'!$K$4:$K$303,"Yes")
A18: Budget used | B18: =IF(B11=0,"",B17/B11)
A19: Forecast final cost | B19: =SUM('Packages'!$N$4:$N$33)
A20: Forecast under / (over) total budget | B20: =B11-B19
A21: Selections total | B21: =SUM('Selections'!$I$4:$I$153)
A23: Takeoffs (Rooms tab)
A24: Internal floor area (m²) | B24: =SUMIFS('Rooms'!$G$4:$G$63,'Rooms'!$C$4:$C$63,"<>Garage",'Rooms'!$C$4:$C$63,"<>External") | F24: Blank area type counts as internal.
A25: Garage floor area (m²) | B25: =SUMIFS('Rooms'!$G$4:$G$63,'Rooms'!$C$4:$C$63,"Garage")
A26: External areas (m²) | B26: =SUMIFS('Rooms'!$G$4:$G$63,'Rooms'!$C$4:$C$63,"External") | F26: Driveways, paving, decks.
A27: Wall paint, one coat (m²) | B27: =SUM('Rooms'!$I$4:$I$63)
A28: Skirting (m) | B28: =SUM('Rooms'!$H$4:$H$63)
A29: Floor covering incl. waste (m²) | B29: =SUM('Rooms'!$J$4:$J$63)
A31: Compliance by stage | B31: Items | C31: N/A | D31: Done | E31: % done
A32: 1. Eligibility | B32: =COUNTIFS('Compliance'!$B$4:$B$79,$A32) | C32: =COUNTIFS('Compliance'!$B$4:$B$79,$A32,'Compliance'!$G$4:$G$79,"N/A") | D32: =COUNTIFS('Compliance'!$B$4:$B$79,$A32,'Compliance'!$G$4:$G$79,"Done") | E32: =IF(B32-C32=0,"",D32/(B32-C32))
A33: 2. Certificate of consent | B33: =COUNTIFS('Compliance'!$B$4:$B$79,$A33) | C33: =COUNTIFS('Compliance'!$B$4:$B$79,$A33,'Compliance'!$G$4:$G$79,"N/A") | D33: =COUNTIFS('Compliance'!$B$4:$B$79,$A33,'Compliance'!$G$4:$G$79,"Done") | E33: =IF(B33-C33=0,"",D33/(B33-C33))
A34: 3. Site, planning & design | B34: =COUNTIFS('Compliance'!$B$4:$B$79,$A34) | C34: =COUNTIFS('Compliance'!$B$4:$B$79,$A34,'Compliance'!$G$4:$G$79,"N/A") | D34: =COUNTIFS('Compliance'!$B$4:$B$79,$A34,'Compliance'!$G$4:$G$79,"Done") | E34: =IF(B34-C34=0,"",D34/(B34-C34))
A35: 4. Building permit & pre-start | B35: =COUNTIFS('Compliance'!$B$4:$B$79,$A35) | C35: =COUNTIFS('Compliance'!$B$4:$B$79,$A35,'Compliance'!$G$4:$G$79,"N/A") | D35: =COUNTIFS('Compliance'!$B$4:$B$79,$A35,'Compliance'!$G$4:$G$79,"Done") | E35: =IF(B35-C35=0,"",D35/(B35-C35))
A36: 5. Health & safety (WorkSafe Victoria) | B36: =COUNTIFS('Compliance'!$B$4:$B$79,$A36) | C36: =COUNTIFS('Compliance'!$B$4:$B$79,$A36,'Compliance'!$G$4:$G$79,"N/A") | D36: =COUNTIFS('Compliance'!$B$4:$B$79,$A36,'Compliance'!$G$4:$G$79,"Done") | E36: =IF(B36-C36=0,"",D36/(B36-C36))
A37: 6. Insurance | B37: =COUNTIFS('Compliance'!$B$4:$B$79,$A37) | C37: =COUNTIFS('Compliance'!$B$4:$B$79,$A37,'Compliance'!$G$4:$G$79,"N/A") | D37: =COUNTIFS('Compliance'!$B$4:$B$79,$A37,'Compliance'!$G$4:$G$79,"Done") | E37: =IF(B37-C37=0,"",D37/(B37-C37))
A38: 7. Engaging trades | B38: =COUNTIFS('Compliance'!$B$4:$B$79,$A38) | C38: =COUNTIFS('Compliance'!$B$4:$B$79,$A38,'Compliance'!$G$4:$G$79,"N/A") | D38: =COUNTIFS('Compliance'!$B$4:$B$79,$A38,'Compliance'!$G$4:$G$79,"Done") | E38: =IF(B38-C38=0,"",D38/(B38-C38))
A39: 8. During construction | B39: =COUNTIFS('Compliance'!$B$4:$B$79,$A39) | C39: =COUNTIFS('Compliance'!$B$4:$B$79,$A39,'Compliance'!$G$4:$G$79,"N/A") | D39: =COUNTIFS('Compliance'!$B$4:$B$79,$A39,'Compliance'!$G$4:$G$79,"Done") | E39: =IF(B39-C39=0,"",D39/(B39-C39))
A40: 9. Completion & occupancy | B40: =COUNTIFS('Compliance'!$B$4:$B$79,$A40) | C40: =COUNTIFS('Compliance'!$B$4:$B$79,$A40,'Compliance'!$G$4:$G$79,"N/A") | D40: =COUNTIFS('Compliance'!$B$4:$B$79,$A40,'Compliance'!$G$4:$G$79,"Done") | E40: =IF(B40-C40=0,"",D40/(B40-C40))
A41: 10. Records & selling | B41: =COUNTIFS('Compliance'!$B$4:$B$79,$A41) | C41: =COUNTIFS('Compliance'!$B$4:$B$79,$A41,'Compliance'!$G$4:$G$79,"N/A") | D41: =COUNTIFS('Compliance'!$B$4:$B$79,$A41,'Compliance'!$G$4:$G$79,"Done") | E41: =IF(B41-C41=0,"",D41/(B41-C41))
A42: 11. Finance & tax | B42: =COUNTIFS('Compliance'!$B$4:$B$79,$A42) | C42: =COUNTIFS('Compliance'!$B$4:$B$79,$A42,'Compliance'!$G$4:$G$79,"N/A") | D42: =COUNTIFS('Compliance'!$B$4:$B$79,$A42,'Compliance'!$G$4:$G$79,"Done") | E42: =IF(B42-C42=0,"",D42/(B42-C42))
A43: All stages | B43: =SUM(B32:B42) | C43: =SUM(C32:C42) | D43: =SUM(D32:D42) | E43: =IF(B43-C43=0,"",D43/(B43-C43))
A45: Needs attention | B45: Count
...

Sheet Project
A1: Project
A2: The basics, always at hand. Yellow cells are yours to fill in.
A4: Project | C4: Notes
A5: Project name
A6: Site address
A7: Lot / plan of subdivision
A8: Title volume / folio
A9: Owner-builder(s)
A10: Phone
A11: Email
A12: Current gateway | B12: G0
A13: Target start
A14: Target finish
A15: Money
A16: Total budget inc GST ($)
A17: Contingency (%) | B17: 0.12 | C17: 10–15% is typical. Owner-builders often underestimate site works, services and finishes.
A18: Lender
A19: Approvals
A20: Certificate of consent no.
A21: Relevant building surveyor
A22: Building permit no.
A23: Planning permit no. (if any)
A24: Site & design
A25: Soil classification (AS 2870)
A26: Wind classification
A27: BAL rating (if bushfire prone)
A28: Energy rating (stars)
A29: Google Drive
A30: Project folder link | C30: Paste your project folder link (any provider), or let Owner Builder > Set up Drive folders fill it in Google Sheets.

Sheet Q&A
A1: Owner-builder Q&A (Victoria)
A2: Plain-English answers, grouped by topic. Read-only. General information, checked September 2026, not legal advice.
A3: Topic | B3: Question | C3: Answer
A4: Getting started | B4: What is an owner-builder? | C4: An owner-builder is a landowner who takes legal responsibility for domestic building work on their own land, instead of engaging a registered builder to manage the whole job. You take on the builder's responsibilities: quality, compliance, safety, and coordinating and paying trades. You can do some work yourself and hire trades for the rest.
A5: Getting started | B5: Do I have to do the building work myself? | C5: No. Most owner-builders act as project manager and engage trades for most of the work. You can do the non-licensed work yourself if you're capable, such as some carpentry, painting or landscaping. Plumbing, gasfitting and electrical work must always be done by licensed practitioners.
A6: Getting started | B6: How much can I really save? | C6: A builder's margin and overheads are commonly 15–25% of the build cost. Realistic owner-builder savings are often 10–20% after allowing for your time, mistakes, higher finance costs and missed trade discounts. Savings come from managing well, not just from cutting out the builder.
A7: Getting started | B7: How long does an owner-build take? | C7: Plan on 18–24 months from idea to occupancy for a typical new home. That's roughly 6–11 months of design, approvals and procurement, then 9–13 months on site. Owner-builders working part-time usually take longer. See the gateways program.
A8: Getting started | B8: What skills do I need? | C8: Organisation matters more than trade skills. You'll be reading plans, scheduling, negotiating, checking quality, managing money and paperwork, and keeping people safe. If you run projects or a household budget well, you're most of the way there. Owner Builder in a Box fills in the rest.
A9: Eligibility & certificate of consent | B9: When do I need a certificate of consent? | C9: When the value of the domestic building work is over $20,000 (it was $16,000 before 1 July 2026). Value means labour plus materials plus GST, including a market value for your own labour. Below that you can owner-build without consent, but you still need any building permit the work requires.
A10: Eligibility & certificate of consent | B10: Who is eligible? | C10: • You own the land, or you're a director of the owning company or a beneficiary of the owning trust • The work is for a single dwelling (or ancillary to it) • You live in it, or intend to (not required for a small second dwelling) • You're not in the business of building • No owner-builder permit in the past 5 years (with exceptions) • You've passed the BPC eLearning assessment and done construction induction training See the eligibility checklist.
A11: Eligibility & certificate of consent | B11: What is the eLearning assessment? | C11: A free online course and assessment run by the Building and Plumbing Commission. It covers your legal responsibilities, safety, contracts and the building process, and takes about 2–3 hours. You need a pass before applying for consent.
A12: Eligibility & certificate of consent | B12: Can I owner-build again within five years? | C12: Generally not on a different property. The exceptions are further work on the same home, building a small second dwelling, or an exemption granted by the BPC for special circumstances such as a substantial change in circumstances or hardship.
A13: Eligibility & certificate of consent | B13: Can I owner-build if my partner and I own the land together? | C13: Yes. Each owner-builder named needs to meet the requirements. The five-year rule also looks at people you co-own, or have co-owned, property with, so check both your histories.
A14: Eligibility & certificate of consent | B14: Can I owner-build a house to sell or rent out? | C14: Owner-builder consent is for a home you live in or intend to live in, apart from a small second dwelling. Building to sell or rent can put you "in the business of building", which requires registration.
... A42: Selling & after completion | B42: Am I liable for defects after I finish? | C42: If you sell, the buyer can rely on statutory warranties for owner-builder work for a period, and the insurance scheme backs claims. In practice that's why the defects report and insurance exist. Build it right, document it, and fix issues before sale.

Sheet Guides
A1: Buying guides & specs
A2: Stage-by-stage: the standards that apply, the spec to confirm and what to ask suppliers. Read-only. Content checked September 2026.
A3: Stage | B3: Topic | C3: Standards | D3: Spec to confirm | E3: Ask the supplier / trade
A4: Base stage | B4: Concrete footings & slab | C4: AS 2870 (residential slabs & footings), AS 3600 (concrete structures). | D4: • Spec to confirm with your engineer: slab type (waffle or raft), concrete strength (typically N20–N32 MPa), slump, mesh (e.g. SL82), bar sizes, edge beam depths, cover to steel. • Vapour barrier: 0.2 mm polyethylene, lapped and taped. Check the energy report for slab-edge insulation. • Termite management to AS 3660.1: physical barrier or chemical. Get the certificate and durable notice. | E4: Is pump hire included? What's the allowance for over-dig and extra concrete? Who books the pre-pour inspection? Will you give me delivery dockets showing MPa?
A5: Base stage | B5: Site drainage & stormwater | D5: • Pipe class and diameter per the engineer's drainage plan (commonly 90 mm and 100 mm PVC). • Rainwater tank size if your energy or water compliance relies on it (often 2,000 L or more connected to toilets or laundry). • Connection to the legal point of discharge. Your plumber lodges a compliance certificate.
A6: Frame & roof | B6: Wall frames & roof trusses | C6: AS 1684 (timber framing), AS 4440 (nail-plated trusses), NASH standard for light steel. | D6: • Timber grade: MGP10 / MGP12 pine is standard. Use H2 treated in termite zones, or light-gauge steel. • Wind classification (e.g. N2, N3) from your engineer. It drives tie-downs and bracing. • Get the frame & truss layout, design certificate and bracing plan with the delivery. | E6: Is it pre-cut or prefabricated? Are lintels, beams and bracing included? What's the lead time? Do you set out the trusses on site?
A7: Frame & roof | B7: Roofing: metal or tiles | C7: AS 1562.1 (metal roofing), AS 2050 (tiles), AS 3959 (bushfire). | D7: • Metal: 0.42 mm BMT is standard. Choose the colour's solar absorptance to match the energy report. • Anticon or sarking blanket for thermal and condensation control (NCC 2022 condensation rules). • Gutter overflow provisions and downpipe spacing per AS/NZS 3500.3. • BAL-rated ember guards and screens if you're in a bushfire prone area.
A8: Lock-up | B8: Windows & external doors | C8: AS 2047 (windows), AS 1288 (glass selection), AS 3959 (BAL). | D8: • Use the U-value and SHGC in your energy report. They are part of your 7-star compliance and must be matched. • Double glazing in thermally broken or uPVC frames is typical for 7-star compliance in Victoria. • Wind rating to match the site's wind class. BAL rating if required. • Keep the WERS label and AS 2047 certificate for your building surveyor. | E8: Do these U-value and SHGC figures match my energy report? What's the lead time? Are flashings and reveals included? Is there a warranty on hardware and seals?
A9: Lock-up | B9: Wall wrap, cladding & bricks | D9: • Vapour-permeable wall wrap (NCC 2022 condensation provisions). Check its class against the specification. • Bricks: order about 5% extra from the same batch to avoid colour variation. Check wall ties and weep holes. • Fibre cement, timber or metal cladding: fix it to the manufacturer's installation guide. Warranties depend on it.
A10: Services | B10: Insulation | D10: Standard: AS/NZS 4859.1. Values come from your energy report. • Typical Victorian 7-star: ceiling around R6.0, external walls around R2.5, plus underfloor if the floor is suspended. • Photograph every wall before plaster. The building surveyor may ask for an installation certificate.
A11: Services | B11: Hot water, heating & all-electric homes | D11: • New Victorian homes that need a planning permit (applied for from 1 January 2024) can't connect to reticulated gas. All-electric is the default choice anyway. • A heat-pump hot water system scores well in the NCC 2022 whole-of-home energy budget. • Reverse-cycle split or ducted systems: check the energy rating, zoning and the refrigerant licence (ARCtick) of the installer. • Solar PV: use a Solar Accreditation Australia (formerly CEC) accredited installer if you want rebates. Check Solar Victoria.
A12: Services | B12: Electrical: switchboard, lighting, smoke alarms | C12: AS/NZS 3000 (wiring rules), AS 3786 (smoke alarms). | D12: • RCD (safety switch) protection on all final sub-circuits. • Hardwired, interconnected smoke alarms in the locations the NCC requires. • Plan the points before rough-in: walk every room in My Build and note GPOs, switches, data and TV. • Think ahead: an EV charger circuit, induction cooktop capacity, battery-ready switchboard.
A13: Services | B13: Plumbing fixtures & tapware | D13: • Only buy WaterMark-certified products. Plumbers can refuse to install anything else, and it may not pass inspection. • Check WELS water ratings (star rating and litres per minute). • Hot water to bathrooms must be delivered at a maximum of 50°C (tempering or thermostatic valve per AS/NZS 3500.4).
A14: Fit-out | B14: Wet areas: waterproofing & tiles | D14: Standard: AS 3740 (waterproofing of domestic wet areas). • Get a waterproofing certificate for every wet area. The building surveyor needs it. • Slip resistance: use P3 or better for wet-area floors and P4–P5 for outdoor areas (AS 4586). • Order about 10% extra tiles from one batch (15% for diagonal or herringbone). My Build's room calculator does this for you.
A15: Fit-out | B15: Kitchen, benchtops & joinery | D15: • Engineered stone is banned in Australia from 1 July 2024. Consider porcelain, sintered stone, natural stone, laminate or timber. • Board: E0 / E1 low-formaldehyde, moisture-resistant under sinks. • Sign off shop drawings. Check the appliance cut-out sizes and ventilation clearances first. • Appliances: use the Energy Rating label, and check the cooktop's electrical load with your electrician.
A16: Fit-out | B16: Paint, flooring & finishes | D16: • Low-VOC, washable paints for living areas. Mould-resistant paint for wet areas. Record the colour codes in My Build. • Flooring: acclimatise timber before laying. Check the moisture content of the slab. • Keep every product's warranty registration and care guide for the handover file.
A17: How to buy | B17: Getting trade pricing as an owner-builder | D17: • Open trade accounts with your building permit and certificate of consent. Many suppliers give owner-builders a builder's discount. • Bundle orders by stage (e.g. all frame hardware together) and ask for a project price. • Compare supply-only prices against supply & install quotes using the tender tool.
A18: How to buy | B18: Deliveries, storage & checking goods | D18: • Time deliveries to the program. Early deliveries get stolen or damaged; late ones stop trades. • Check quantities and condition on arrival and note damage on the docket before you sign it. • Store off the ground, covered and secure. Photograph deliveries for insurance. • Keep every docket and invoice against its trade package in your budget.

Sheet Reference
A1: Reference
A2: Key numbers, contract types, tendering and who does what. Read-only.
A3: Key numbers
A4: Rule | B4: Figure | C4: Where it comes from
A5: Certificate of consent required | B5: Work over $20,000 (was $16,000 before 1 July 2026) | C5: Building Act 1993, BPC
A6: Owner-builder permit frequency | B6: 1 every 5 years (exemptions apply) | C6: Building Act s25E, BPC
A7: Major domestic building contract / registered builder | B7: Work over $10,000 (proposed increase to $20,000) | C7: Domestic Building Contracts Act 1995
A8: Principal contractor (OHS) | B8: Projects of $350,000 or more | C8: OHS Regulations 2017
A9: Selling: defects report & insurance | B9: Within 6 yrs 6 mths of completion. Report ≤ 6 months old | C9: Building Act s137B
A10: Energy efficiency (new homes) | B10: 7-star NatHERS + whole-of-home | C10: NCC 2022, Victoria from 1 May 2024
A11: Building permit levy | B11: Work over $10,000 | C11: Building Act, collected by the RBS
A13: Contract types
A14: Type | B14: How it's priced | C14: Best for | D14: Watch out for
A15: Lump sum (fixed price) | B15: One price for a defined scope | C15: Well-documented packages: slab, roof, electrical | D15: Vague scope means variations. Exclusions hide cost.
A16: Schedule of rates | B16: $ per m², per point, per 1,000 bricks | C16: Measurable work: bricks, plaster, tiles | D16: You carry the quantity risk. Measure it yourself.
A17: Labour only | B17: Labour price; you supply the materials | C17: Carpentry, fixing, painting | D17: You carry material risk and waste. Deliveries must be on time.
A18: Supply only | B18: Materials delivered | C18: Frames, trusses, windows, appliances | D18: Check against the plans. Delivery dates. Damage on delivery.
A19: Supply & install | B19: Materials + labour | C19: Roofing, insulation, cabinetry | D19: Confirm the spec and brand. Warranty covers both parts.
A20: Cost plus / do & charge | B20: Actual cost + margin or hourly rate | C20: Small unknowns, repairs, excavation in rock | D20: No price certainty. Cap it and require daily dockets.
A22: What goes in an RFQ pack
A23: What goes in an RFQ pack
A24: Cover letter: package, address, closing date, contact
A25: Scope of works + inclusions list
A26: Drawings & specification (with revision numbers)
A27: Engineering & energy report extracts
A28: Program: target start and duration
A29: Site info: access, power, water, slope, photos
A30: Your draft trade agreement (see Contracts)
A31: Pricing schedule so every quote breaks down the same way
A32: What to return: licence, insurance, ABN, SWMS, references
A34: Levelling: making quotes comparable
... A62: Who does what (RACI)
A63: Activity | B63: You (owner-builder) | C63: Designer / engineer | D63: Building surveyor | E63: Trades | F63: Lender
A64: Design brief & scope | B64: A/R | C64: C | D64: I | E64: – | F64: I
A65: Working drawings & engineering | B65: A | C65: R | D65: C | E65: – | F65: I
A66: Certificate of consent | B66: A/R | C66: – | D66: I | E66: – | F66: I
A67: Building permit | B67: A | C67: C | D67: R | E67: – | F67: I
A68: Tendering & contracts | B68: A/R | C68: C | D68: – | E68: C | F68: I
A69: Site safety & coordination | B69: A/R | C69: – | D69: – | E69: R (own work) | F69: –
A70: Mandatory inspections | B70: A (notify) | C70: C | D70: R | E70: C | F70: I
...

Sheet Gate Review
A1: Gate review
A2: At each gate decide Go, Hold or Stop. A gate is ready when every exit check on the Gateways tab is Yes.
A3: Gate | B3: Name | C3: Purpose | D3: Entry criteria met | E3: Deliverables done | F3: Exit checks | G3: Exit checks done | H3: Exit % | I3: Ready to pass? | J3: Decision | K3: Decision check | L3: Decision date | M3: Decision guide | N3: Typical budget spent | O3: Typical duration | P3: Notes
A4: G0 | B4: Feasibility & eligibility | C4: Can I, should I, and can I afford to owner-build? | D4: =COUNTIFS('Gateways'!$A$4:$A$114,A4,'Gateways'!$C$4:$C$114,"Entry criteria",'Gateways'!$E$4:$E$114,"Yes")&" of "&COUNTIFS('Gateways'!$A$4:$A$114,A4,'Gateways'!$C$4:$C$114,"Entry criteria") | E4: =COUNTIFS('Gateways'!$A$4:$A$114,A4,'Gateways'!$C$4:$C$114,"Deliverable",'Gateways'!$E$4:$E$114,"Yes")&" of "&COUNTIFS('Gateways'!$A$4:$A$114,A4,'Gateways'!$C$4:$C$114,"Deliverable") | F4: =COUNTIFS('Gateways'!$A$4:$A$114,A4,'Gateways'!$C$4:$C$114,"Exit check") | G4: =COUNTIFS('Gateways'!$A$4:$A$114,A4,'Gateways'!$C$4:$C$114,"Exit check",'Gateways'!$E$4:$E$114,"Yes") | H4: =IF(F4=0,"",G4/F4) | I4: =IF(F4=0,"",IF(G4=F4,"Ready","Not yet")) | K4: =IF(AND(J4="Go",I4<>"Ready"),"Go recorded, exit checks open","") | M4: Go to concept, or Stop and consider a builder or part-build instead. | N4: ~0–1% | O4: 1–3 months (with G1)
A5: G1 | B5: Concept & budget | C5: Lock the brief, the concept and the money. | D5: =COUNTIFS('Gateways'!$A$4:$A$114,A5,'Gateways'!$C$4:$C$114,"Entry criteria",'Gateways'!$E$4:$E$114,"Yes")&" of "&COUNTIFS('Gateways'!$A$4:$A$114,A5,'Gateways'!$C$4:$C$114,"Entry criteria") | E5: =COUNTIFS('Gateways'!$A$4:$A$114,A5,'Gateways'!$C$4:$C$114,"Deliverable",'Gateways'!$E$4:$E$114,"Yes")&" of "&COUNTIFS('Gateways'!$A$4:$A$114,A5,'Gateways'!$C$4:$C$114,"Deliverable") | F5: =COUNTIFS('Gateways'!$A$4:$A$114,A5,'Gateways'!$C$4:$C$114,"Exit check") | G5: =COUNTIFS('Gateways'!$A$4:$A$114,A5,'Gateways'!$C$4:$C$114,"Exit check",'Gateways'!$E$4:$E$114,"Yes") | H5: =IF(F5=0,"",G5/F5) | I5: =IF(F5=0,"",IF(G5=F5,"Ready","Not yet")) | K5: =IF(AND(J5="Go",I5<>"Ready"),"Go recorded, exit checks open","") | M5: Go to detailed design, or Hold and value-manage the concept. | N5: ~2–3% | O5: 1–3 months (with G0)
A6: G2 | B6: Design & approvals | C6: Everything you need for a building permit. | D6: =COUNTIFS('Gateways'!$A$4:$A$114,A6,'Gateways'!$C$4:$C$114,"Entry criteria",'Gateways'!$E$4:$E$114,"Yes")&" of "&COUNTIFS('Gateways'!$A$4:$A$114,A6,'Gateways'!$C$4:$C$114,"Entry criteria") | E6: =COUNTIFS('Gateways'!$A$4:$A$114,A6,'Gateways'!$C$4:$C$114,"Deliverable",'Gateways'!$E$4:$E$114,"Yes")&" of "&COUNTIFS('Gateways'!$A$4:$A$114,A6,'Gateways'!$C$4:$C$114,"Deliverable") | F6: =COUNTIFS('Gateways'!$A$4:$A$114,A6,'Gateways'!$C$4:$C$114,"Exit check") | G6: =COUNTIFS('Gateways'!$A$4:$A$114,A6,'Gateways'!$C$4:$C$114,"Exit check",'Gateways'!$E$4:$E$114,"Yes") | H6: =IF(F6=0,"",G6/F6) | I6: =IF(F6=0,"",IF(G6=F6,"Ready","Not yet")) | K6: =IF(AND(J6="Go",I6<>"Ready"),"Go recorded, exit checks open","") | M6: Go to procurement, or Hold for design changes. | N6: ~5% | O6: 2–6 months
A7: G3 | B7: Procurement & permit | C7: Right trades, right price, right paperwork. Ready to start. | D7: =COUNTIFS('Gateways'!$A$4:$A$114,A7,'Gateways'!$C$4:$C$114,"Entry criteria",'Gateways'!$E$4:$E$114,"Yes")&" of "&COUNTIFS('Gateways'!$A$4:$A$114,A7,'Gateways'!$C$4:$C$114,"Entry criteria") | E7: =COUNTIFS('Gateways'!$A$4:$A$114,A7,'Gateways'!$C$4:$C$114,"Deliverable",'Gateways'!$E$4:$E$114,"Yes")&" of "&COUNTIFS('Gateways'!$A$4:$A$114,A7,'Gateways'!$C$4:$C$114,"Deliverable") | F7: =COUNTIFS('Gateways'!$A$4:$A$114,A7,'Gateways'!$C$4:$C$114,"Exit check") | G7: =COUNTIFS('Gateways'!$A$4:$A$114,A7,'Gateways'!$C$4:$C$114,"Exit check",'Gateways'!$E$4:$E$114,"Yes") | H7: =IF(F7=0,"",G7/F7) | I7: =IF(F7=0,"",IF(G7=F7,"Ready","Not yet")) | K7: =IF(AND(J7="Go",I7<>"Ready"),"Go recorded, exit checks open","") | M7: Go to site, or Hold until the price and paperwork are right. | N7: ~8% | O7: 1–2 months
A8: G4 | B8: Site works & base | C8: Out of the ground: set-out, services, footings and slab. | D8: =COUNTIFS('Gateways'!$A$4:$A$114,A8,'Gateways'!$C$4:$C$114,"Entry criteria",'Gateways'!$E$4:$E$114,"Yes")&" of "&COUNTIFS('Gateways'!$A$4:$A$114,A8,'Gateways'!$C$4:$C$114,"Entry criteria") | E8: =COUNTIFS('Gateways'!$A$4:$A$114,A8,'Gateways'!$C$4:$C$114,"Deliverable",'Gateways'!$E$4:$E$114,"Yes")&" of "&COUNTIFS('Gateways'!$A$4:$A$114,A8,'Gateways'!$C$4:$C$114,"Deliverable") | F8: =COUNTIFS('Gateways'!$A$4:$A$114,A8,'Gateways'!$C$4:$C$114,"Exit check") | G8: =COUNTIFS('Gateways'!$A$4:$A$114,A8,'Gateways'!$C$4:$C$114,"Exit check",'Gateways'!$E$4:$E$114,"Yes") | H8: =IF(F8=0,"",G8/F8) | I8: =IF(F8=0,"",IF(G8=F8,"Ready","Not yet")) | K8: =IF(AND(J8="Go",I8<>"Ready"),"Go recorded, exit checks open","") | M8: Go to frame. | N8: ~15–20% | O8: 4–8 weeks
A9: G5 | B9: Frame & lock-up | C9: Structure, roof, windows and doors. Weather-tight and secure. | D9: =COUNTIFS('Gateways'!$A$4:$A$114,A9,'Gateways'!$C$4:$C$114,"Entry criteria",'Gateways'!$E$4:$E$114,"Yes")&" of "&COUNTIFS('Gateways'!$A$4:$A$114,A9,'Gateways'!$C$4:$C$114,"Entry criteria") | E9: =COUNTIFS('Gateways'!$A$4:$A$114,A9,'Gateways'!$C$4:$C$114,"Deliverable",'Gateways'!$E$4:$E$114,"Yes")&" of "&COUNTIFS('Gateways'!$A$4:$A$114,A9,'Gateways'!$C$4:$C$114,"Deliverable") | F9: =COUNTIFS('Gateways'!$A$4:$A$114,A9,'Gateways'!$C$4:$C$114,"Exit check") | G9: =COUNTIFS('Gateways'!$A$4:$A$114,A9,'Gateways'!$C$4:$C$114,"Exit check",'Gateways'!$E$4:$E$114,"Yes") | H9: =IF(F9=0,"",G9/F9) | I9: =IF(F9=0,"",IF(G9=F9,"Ready","Not yet")) | K9: =IF(AND(J9="Go",I9<>"Ready"),"Go recorded, exit checks open","") | M9: Go to fit-out. | N9: ~45–55% | O9: 8–12 weeks
A10: G6 | B10: Fit-out & fixing | C10: Plaster to paint, wet areas, kitchen, fit-off. | D10: =COUNTIFS('Gateways'!$A$4:$A$114,A10,'Gateways'!$C$4:$C$114,"Entry criteria",'Gateways'!$E$4:$E$114,"Yes")&" of "&COUNTIFS('Gateways'!$A$4:$A$114,A10,'Gateways'!$C$4:$C$114,"Entry criteria") | E10: =COUNTIFS('Gateways'!$A$4:$A$114,A10,'Gateways'!$C$4:$C$114,"Deliverable",'Gateways'!$E$4:$E$114,"Yes")&" of "&COUNTIFS('Gateways'!$A$4:$A$114,A10,'Gateways'!$C$4:$C$114,"Deliverable") | F10: =COUNTIFS('Gateways'!$A$4:$A$114,A10,'Gateways'!$C$4:$C$114,"Exit check") | G10: =COUNTIFS('Gateways'!$A$4:$A$114,A10,'Gateways'!$C$4:$C$114,"Exit check",'Gateways'!$E$4:$E$114,"Yes") | H10: =IF(F10=0,"",G10/F10) | I10: =IF(F10=0,"",IF(G10=F10,"Ready","Not yet")) | K10: =IF(AND(J10="Go",I10<>"Ready"),"Go recorded, exit checks open","") | M10: Go to final. | N10: ~85–90% | O10: 12–20 weeks
A11: G7 | B11: Completion & handover | C11: Occupancy, close-out and your handover file. | D11: =COUNTIFS('Gateways'!$A$4:$A$114,A11,'Gateways'!$C$4:$C$114,"Entry criteria",'Gateways'!$E$4:$E$114,"Yes")&" of "&COUNTIFS('Gateways'!$A$4:$A$114,A11,'Gateways'!$C$4:$C$114,"Entry criteria") | E11: =COUNTIFS('Gateways'!$A$4:$A$114,A11,'Gateways'!$C$4:$C$114,"Deliverable",'Gateways'!$E$4:$E$114,"Yes")&" of "&COUNTIFS('Gateways'!$A$4:$A$114,A11,'Gateways'!$C$4:$C$114,"Deliverable") | F11: =COUNTIFS('Gateways'!$A$4:$A$114,A11,'Gateways'!$C$4:$C$114,"Exit check") | G11: =COUNTIFS('Gateways'!$A$4:$A$114,A11,'Gateways'!$C$4:$C$114,"Exit check",'Gateways'!$E$4:$E$114,"Yes") | H11: =IF(F11=0,"",G11/F11) | I11: =IF(F11=0,"",IF(G11=F11,"Ready","Not yet")) | K11: =IF(AND(J11="Go",I11<>"Ready"),"Go recorded, exit checks open","") | M11: Close the project. Welcome home. | N11: 100% | O11: 2–6 weeks

Sheet Gateways
A1: Gateways G0 to G7
A2: Tick each entry criterion, deliverable and exit check as it's met. A gate is ready to pass when every exit check is Yes (see Gate Review).
A3: Gate | B3: Gate name | C3: Type | D3: Item | E3: Done? | F3: Date | G3: Evidence Doc ID | H3: Drive folder (suggested) | I3: Folder | J3: Notes
A4: G0 | B4: Feasibility & eligibility | C4: Entry criteria | D4: You own, or are buying, the land | I4: =IF(H4="","",IF(IFERROR(INDEX('Google Drive Map'!$G$4:$G$33,MATCH(H4,'Google Drive Map'!$B$4:$B$33,0))&"","")="","",HYPERLINK(INDEX('Google Drive Map'!$G$4:$G$33,MATCH(H4,'Google Drive Map'!$B$4:$B$33,0)),"Open")))
A5: G0 | B5: Feasibility & eligibility | C5: Entry criteria | D5: You have a rough idea of the home you want | I5: =IF(H5="","",IF(IFERROR(INDEX('Google Drive Map'!$G$4:$G$33,MATCH(H5,'Google Drive Map'!$B$4:$B$33,0))&"","")="","",HYPERLINK(INDEX('Google Drive Map'!$G$4:$G$33,MATCH(H5,'Google Drive Map'!$B$4:$B$33,0)),"Open")))
A6: G0 | B6: Feasibility & eligibility | C6: Entry criteria | D6: You know how much time you can commit each week | I6: =IF(H6="","",IF(IFERROR(INDEX('Google Drive Map'!$G$4:$G$33,MATCH(H6,'Google Drive Map'!$B$4:$B$33,0))&"","")="","",HYPERLINK(INDEX('Google Drive Map'!$G$4:$G$33,MATCH(H6,'Google Drive Map'!$B$4:$B$33,0)),"Open")))
A7: G0 | B7: Feasibility & eligibility | C7: Deliverable | D7: Eligibility self-check (s25E) | H7: 01 Eligibility, Land & Planning | I7: =IF(H7="","",IF(IFERROR(INDEX('Google Drive Map'!$G$4:$G$33,MATCH(H7,'Google Drive Map'!$B$4:$B$33,0))&"","")="","",HYPERLINK(INDEX('Google Drive Map'!$G$4:$G$33,MATCH(H7,'Google Drive Map'!$B$4:$B$33,0)),"Open")))
A8: G0 | B8: Feasibility & eligibility | C8: Deliverable | D8: Title, zoning & overlay review | H8: 01 Eligibility, Land & Planning | I8: =IF(H8="","",IF(IFERROR(INDEX('Google Drive Map'!$G$4:$G$33,MATCH(H8,'Google Drive Map'!$B$4:$B$33,0))&"","")="","",HYPERLINK(INDEX('Google Drive Map'!$G$4:$G$33,MATCH(H8,'Google Drive Map'!$B$4:$B$33,0)),"Open")))
A9: G0 | B9: Feasibility & eligibility | C9: Deliverable | D9: Order-of-magnitude budget ($/m² × area) | H9: 03 Permits, Insurance & Finance | I9: =IF(H9="","",IF(IFERROR(INDEX('Google Drive Map'!$G$4:$G$33,MATCH(H9,'Google Drive Map'!$B$4:$B$33,0))&"","")="","",HYPERLINK(INDEX('Google Drive Map'!$G$4:$G$33,MATCH(H9,'Google Drive Map'!$B$4:$B$33,0)),"Open")))
A10: G0 | B10: Feasibility & eligibility | C10: Deliverable | D10: Finance conversation with an owner-builder-friendly lender | H10: 03 Permits, Insurance & Finance | I10: =IF(H10="","",IF(IFERROR(INDEX('Google Drive Map'!$G$4:$G$33,MATCH(H10,'Google Drive Map'!$B$4:$B$33,0))&"","")="","",HYPERLINK(INDEX('Google Drive Map'!$G$4:$G$33,MATCH(H10,'Google Drive Map'!$B$4:$B$33,0)),"Open")))
A11: G0 | B11: Feasibility & eligibility | C11: Deliverable | D11: Honest skills & time assessment | H11: 00 Project Register | I11: =IF(H11="","",IF(IFERROR(INDEX('Google Drive Map'!$G$4:$G$33,MATCH(H11,'Google Drive Map'!$B$4:$B$33,0))&"","")="","",HYPERLINK(INDEX('Google Drive Map'!$G$4:$G$33,MATCH(H11,'Google Drive Map'!$B$4:$B$33,0)),"Open")))
A12: G0 | B12: Feasibility & eligibility | C12: Exit check | D12: Eligible, or exemption pathway known | I12: =IF(H12="","",IF(IFERROR(INDEX('Google Drive Map'!$G$4:$G$33,MATCH(H12,'Google Drive Map'!$B$4:$B$33,0))&"","")="","",HYPERLINK(INDEX('Google Drive Map'!$G$4:$G$33,MATCH(H12,'Google Drive Map'!$B$4:$B$33,0)),"Open")))
A13: G0 | B13: Feasibility & eligibility | C13: Exit check | D13: No title or planning showstoppers | I13: =IF(H13="","",IF(IFERROR(INDEX('Google Drive Map'!$G$4:$G$33,MATCH(H13,'Google Drive Map'!$B$4:$B$33,0))&"","")="","",HYPERLINK(INDEX('Google Drive Map'!$G$4:$G$33,MATCH(H13,'Google Drive Map'!$B$4:$B$33,0)),"Open")))
A14: G0 | B14: Feasibility & eligibility | C14: Exit check | D14: Budget and finance roughly align | I14: =IF(H14="","",IF(IFERROR(INDEX('Google Drive Map'!$G$4:$G$33,MATCH(H14,'Google Drive Map'!$B$4:$B$33,0))&"","")="","",HYPERLINK(INDEX('Google Drive Map'!$G$4:$G$33,MATCH(H14,'Google Drive Map'!$B$4:$B$33,0)),"Open")))
A15: G0 | B15: Feasibility & eligibility | C15: Exit check | D15: Household agrees on time, stress and risk | I15: =IF(H15="","",IF(IFERROR(INDEX('Google Drive Map'!$G$4:$G$33,MATCH(H15,'Google Drive Map'!$B$4:$B$33,0))&"","")="","",HYPERLINK(INDEX('Google Drive Map'!$G$4:$G$33,MATCH(H15,'Google Drive Map'!$B$4:$B$33,0)),"Open")))
A16: G1 | B16: Concept & budget | C16: Entry criteria | D16: G0 passed | I16: =IF(H16="","",IF(IFERROR(INDEX('Google Drive Map'!$G$4:$G$33,MATCH(H16,'Google Drive Map'!$B$4:$B$33,0))&"","")="","",HYPERLINK(INDEX('Google Drive Map'!$G$4:$G$33,MATCH(H16,'Google Drive Map'!$B$4:$B$33,0)),"Open")))
A17: G1 | B17: Concept & budget | C17: Entry criteria | D17: Designer or architect engaged | I17: =IF(H17="","",IF(IFERROR(INDEX('Google Drive Map'!$G$4:$G$33,MATCH(H17,'Google Drive Map'!$B$4:$B$33,0))&"","")="","",HYPERLINK(INDEX('Google Drive Map'!$G$4:$G$33,MATCH(H17,'Google Drive Map'!$B$4:$B$33,0)),"Open")))
A18: G1 | B18: Concept & budget | C18: Entry criteria | D18: Feature & level survey and soil test ordered | I18: =IF(H18="","",IF(IFERROR(INDEX('Google Drive Map'!$G$4:$G$33,MATCH(H18,'Google Drive Map'!$B$4:$B$33,0))&"","")="","",HYPERLINK(INDEX('Google Drive Map'!$G$4:$G$33,MATCH(H18,'Google Drive Map'!$B$4:$B$33,0)),"Open")))
A19: G1 | B19: Concept & budget | C19: Deliverable | D19: Written design brief (rooms, sizes, must-haves, nice-to-haves) | H19: 02 Design & Engineering | I19: =IF(H19="","",IF(IFERROR(INDEX('Google Drive Map'!$G$4:$G$33,MATCH(H19,'Google Drive Map'!$B$4:$B$33,0))&"","")="","",HYPERLINK(INDEX('Google Drive Map'!$G$4:$G$33,MATCH(H19,'Google Drive Map'!$B$4:$B$33,0)),"Open")))
A20: G1 | B20: Concept & budget | C20: Deliverable | D20: Concept plans & room schedule in My Build | H20: 02 Design & Engineering | I20: =IF(H20="","",IF(IFERROR(INDEX('Google Drive Map'!$G$4:$G$33,MATCH(H20,'Google Drive Map'!$B$4:$B$33,0))&"","")="","",HYPERLINK(INDEX('Google Drive Map'!$G$4:$G$33,MATCH(H20,'Google Drive Map'!$B$4:$B$33,0)),"Open")))
A21: G1 | B21: Concept & budget | C21: Deliverable | D21: Elemental cost plan with 10–15% contingency | H21: 03 Permits, Insurance & Finance | I21: =IF(H21="","",IF(IFERROR(INDEX('Google Drive Map'!$G$4:$G$33,MATCH(H21,'Google Drive Map'!$B$4:$B$33,0))&"","")="","",HYPERLINK(INDEX('Google Drive Map'!$G$4:$G$33,MATCH(H21,'Google Drive Map'!$B$4:$B$33,0)),"Open")))
A22: G1 | B22: Concept & budget | C22: Deliverable | D22: Finance pre-approval | H22: 03 Permits, Insurance & Finance | I22: =IF(H22="","",IF(IFERROR(INDEX('Google Drive Map'!$G$4:$G$33,MATCH(H22,'Google Drive Map'!$B$4:$B$33,0))&"","")="","",HYPERLINK(INDEX('Google Drive Map'!$G$4:$G$33,MATCH(H22,'Google Drive Map'!$B$4:$B$33,0)),"Open")))
A23: G1 | B23: Concept & budget | C23: Deliverable | D23: Draft program (target start & finish) | H23: 00 Project Register | I23: =IF(H23="","",IF(IFERROR(INDEX('Google Drive Map'!$G$4:$G$33,MATCH(H23,'Google Drive Map'!$B$4:$B$33,0))&"","")="","",HYPERLINK(INDEX('Google Drive Map'!$G$4:$G$33,MATCH(H23,'Google Drive Map'!$B$4:$B$33,0)),"Open")))
A24: G1 | B24: Concept & budget | C24: Deliverable | D24: First risk register | H24: 00 Project Register | I24: =IF(H24="","",IF(IFERROR(INDEX('Google Drive Map'!$G$4:$G$33,MATCH(H24,'Google Drive Map'!$B$4:$B$33,0))&"","")="","",HYPERLINK(INDEX('Google Drive Map'!$G$4:$G$33,MATCH(H24,'Google Drive Map'!$B$4:$B$33,0)),"Open")))
A25: G1 | B25: Concept & budget | C25: Exit check | D25: Concept fits the budget, including contingency | I25: =IF(H25="","",IF(IFERROR(INDEX('Google Drive Map'!$G$4:$G$33,MATCH(H25,'Google Drive Map'!$B$4:$B$33,0))&"","")="","",HYPERLINK(INDEX('Google Drive Map'!$G$4:$G$33,MATCH(H25,'Google Drive Map'!$B$4:$B$33,0)),"Open")))
A26: G1 | B26: Concept & budget | C26: Exit check | D26: Concept fits the site (setbacks, overlays, fall, BAL) | I26: =IF(H26="","",IF(IFERROR(INDEX('Google Drive Map'!$G$4:$G$33,MATCH(H26,'Google Drive Map'!$B$4:$B$33,0))&"","")="","",HYPERLINK(INDEX('Google Drive Map'!$G$4:$G$33,MATCH(H26,'Google Drive Map'!$B$4:$B$33,0)),"Open")))
A27: G1 | B27: Concept & budget | C27: Exit check | D27: Scope frozen: changes after this cost money | I27: =IF(H27="","",IF(IFERROR(INDEX('Google Drive Map'!$G$4:$G$33,MATCH(H27,'Google Drive Map'!$B$4:$B$33,0))&"","")="","",HYPERLINK(INDEX('Google Drive Map'!$G$4:$G$33,MATCH(H27,'Google Drive Map'!$B$4:$B$33,0)),"Open")))
A28: G2 | B28: Design & approvals | C28: Entry criteria | D28: G1 passed, scope frozen | I28: =IF(H28="","",IF(IFERROR(INDEX('Google Drive Map'!$G$4:$G$33,MATCH(H28,'Google Drive Map'!$B$4:$B$33,0))&"","")="","",HYPERLINK(INDEX('Google Drive Map'!$G$4:$G$33,MATCH(H28,'Google Drive Map'!$B$4:$B$33,0)),"Open")))
A29: G2 | B29: Design & approvals | C29: Entry criteria | D29: Owner-builder eLearning & white card done | I29: =IF(H29="","",IF(IFERROR(INDEX('Google Drive Map'!$G$4:$G$33,MATCH(H29,'Google Drive Map'!$B$4:$B$33,0))&"","")="","",HYPERLINK(INDEX('Google Drive Map'!$G$4:$G$33,MATCH(H29,'Google Drive Map'!$B$4:$B$33,0)),"Open")))
A30: G2 | B30: Design & approvals | C30: Deliverable | D30: Working drawings & specification | H30: 02 Design & Engineering | I30: =IF(H30="","",IF(IFERROR(INDEX('Google Drive Map'!$G$4:$G$33,MATCH(H30,'Google Drive Map'!$B$4:$B$33,0))&"","")="","",HYPERLINK(INDEX('Google Drive Map'!$G$4:$G$33,MATCH(H30,'Google Drive Map'!$B$4:$B$33,0)),"Open")))
A31: G2 | B31: Design & approvals | C31: Deliverable | D31: Engineering: footings, slab, frame, drainage | H31: 02 Design & Engineering | I31: =IF(H31="","",IF(IFERROR(INDEX('Google Drive Map'!$G$4:$G$33,MATCH(H31,'Google Drive Map'!$B$4:$B$33,0))&"","")="","",HYPERLINK(INDEX('Google Drive Map'!$G$4:$G$33,MATCH(H31,'Google Drive Map'!$B$4:$B$33,0)),"Open")))
A32: G2 | B32: Design & approvals | C32: Deliverable | D32: 7-star energy report | H32: 02 Design & Engineering | I32: =IF(H32="","",IF(IFERROR(INDEX('Google Drive Map'!$G$4:$G$33,MATCH(H32,'Google Drive Map'!$B$4:$B$33,0))&"","")="","",HYPERLINK(INDEX('Google Drive Map'!$G$4:$G$33,MATCH(H32,'Google Drive Map'!$B$4:$B$33,0)),"Open")))
A33: G2 | B33: Design & approvals | C33: Deliverable | D33: BAL assessment (if bushfire prone) | H33: 02 Design & Engineering | I33: =IF(H33="","",IF(IFERROR(INDEX('Google Drive Map'!$G$4:$G$33,MATCH(H33,'Google Drive Map'!$B$4:$B$33,0))&"","")="","",HYPERLINK(INDEX('Google Drive Map'!$G$4:$G$33,MATCH(H33,'Google Drive Map'!$B$4:$B$33,0)),"Open")))
A34: G2 | B34: Design & approvals | C34: Deliverable | D34: Planning permit (if required) | H34: 01 Eligibility, Land & Planning | I34: =IF(H34="","",IF(IFERROR(INDEX('Google Drive Map'!$G$4:$G$33,MATCH(H34,'Google Drive Map'!$B$4:$B$33,0))&"","")="","",HYPERLINK(INDEX('Google Drive Map'!$G$4:$G$33,MATCH(H34,'Google Drive Map'!$B$4:$B$33,0)),"Open")))
A35: G2 | B35: Design & approvals | C35: Deliverable | D35: Certificate of consent from the BPC | H35: 01 Eligibility, Land & Planning | I35: =IF(H35="","",IF(IFERROR(INDEX('Google Drive Map'!$G$4:$G$33,MATCH(H35,'Google Drive Map'!$B$4:$B$33,0))&"","")="","",HYPERLINK(INDEX('Google Drive Map'!$G$4:$G$33,MATCH(H35,'Google Drive Map'!$B$4:$B$33,0)),"Open")))
A36: G2 | B36: Design & approvals | C36: Deliverable | D36: Legal point of discharge, easement consents | H36: 01 Eligibility, Land & Planning | I36: =IF(H36="","",IF(IFERROR(INDEX('Google Drive Map'!$G$4:$G$33,MATCH(H36,'Google Drive Map'!$B$4:$B$33,0))&"","")="","",HYPERLINK(INDEX('Google Drive Map'!$G$4:$G$33,MATCH(H36,'Google Drive Map'!$B$4:$B$33,0)),"Open")))
A37: G2 | B37: Design & approvals | C37: Exit check | D37: All documents consistent (drawings = engineering = energy) | I37: =IF(H37="","",IF(IFERROR(INDEX('Google Drive Map'!$G$4:$G$33,MATCH(H37,'Google Drive Map'!$B$4:$B$33,0))&"","")="","",HYPERLINK(INDEX('Google Drive Map'!$G$4:$G$33,MATCH(H37,'Google Drive Map'!$B$4:$B$33,0)),"Open")))
A38: G2 | B38: Design & approvals | C38: Exit check | D38: Certificate of consent issued | I38: =IF(H38="","",IF(IFERROR(INDEX('Google Drive Map'!$G$4:$G$33,MATCH(H38,'Google Drive Map'!$B$4:$B$33,0))&"","")="","",HYPERLINK(INDEX('Google Drive Map'!$G$4:$G$33,MATCH(H38,'Google Drive Map'!$B$4:$B$33,0)),"Open")))
A39: G2 | B39: Design & approvals | C39: Exit check | D39: RBS appointed and fee agreed | I39: =IF(H39="","",IF(IFERROR(INDEX('Google Drive Map'!$G$4:$G$33,MATCH(H39,'Google Drive Map'!$B$4:$B$33,0))&"","")="","",HYPERLINK(INDEX('Google Drive Map'!$G$4:$G$33,MATCH(H39,'Google Drive Map'!$B$4:$B$33,0)),"Open")))
A40: G2 | B40: Design & approvals | C40: Exit check | D40: Cost plan updated to the detailed design | I40: =IF(H40="","",IF(IFERROR(INDEX('Google Drive Map'!$G$4:$G$33,MATCH(H40,'Google Drive Map'!$B$4:$B$33,0))&"","")="","",HYPERLINK(INDEX('Google Drive Map'!$G$4:$G$33,MATCH(H40,'Google Drive Map'!$B$4:$B$33,0)),"Open")))
...

Sheet Compliance
A1: Victorian owner-builder compliance
A2: Every item from the 11-stage checklist. Set Status as you go; use N/A only where the item genuinely doesn't apply to your build.
A3: ID | B3: Stage | C3: Item | D3: Requirement | E3: What it means | F3: Gateway | G3: Status | H3: Date done | I3: Reference / permit no. | J3: Evidence Doc ID | K3: Drive folder | L3: Folder | M3: Notes
A4: el-own | B4: 1. Eligibility | C4: You own the land | D4: Must | E4: Or you're a director of the company, or a beneficiary of the trust, that owns it. Your name must match the title. | F4: G0 | G4: Not started | K4: 01 Eligibility, Land & Planning | L4: =IF(K4="","",IF(IFERROR(INDEX('Google Drive Map'!$G$4:$G$33,MATCH(K4,'Google Drive Map'!$B$4:$B$33,0))&"","")="","",HYPERLINK(INDEX('Google Drive Map'!$G$4:$G$33,MATCH(K4,'Google Drive Map'!$B$4:$B$33,0)),"Open")))
A5: el-single | B5: 1. Eligibility | C5: The work relates to a single domestic dwelling | D5: Must | E5: This includes work ancillary to it, such as a garage, shed, pool or deck. Multi-unit developments are out. | F5: G0 | G5: Not started | K5: 01 Eligibility, Land & Planning | L5: =IF(K5="","",IF(IFERROR(INDEX('Google Drive Map'!$G$4:$G$33,MATCH(K5,'Google Drive Map'!$B$4:$B$33,0))&"","")="","",HYPERLINK(INDEX('Google Drive Map'!$G$4:$G$33,MATCH(K5,'Google Drive Map'!$B$4:$B$33,0)),"Open")))
A6: el-reside | B6: 1. Eligibility | C6: You live in it, or intend to live in it | D6: Must | E6: A small second dwelling on the same lot is exempt from this rule. | F6: G0 | G6: Not started | K6: 01 Eligibility, Land & Planning | L6: =IF(K6="","",IF(IFERROR(INDEX('Google Drive Map'!$G$4:$G$33,MATCH(K6,'Google Drive Map'!$B$4:$B$33,0))&"","")="","",HYPERLINK(INDEX('Google Drive Map'!$G$4:$G$33,MATCH(K6,'Google Drive Map'!$B$4:$B$33,0)),"Open")))
A7: el-business | B7: 1. Eligibility | C7: You're not in the "business of building" | D7: Must | E7: Owner-building repeatedly for profit is treated as running a building business and needs registration. | F7: G0 | G7: Not started | K7: 01 Eligibility, Land & Planning | L7: =IF(K7="","",IF(IFERROR(INDEX('Google Drive Map'!$G$4:$G$33,MATCH(K7,'Google Drive Map'!$B$4:$B$33,0))&"","")="","",HYPERLINK(INDEX('Google Drive Map'!$G$4:$G$33,MATCH(K7,'Google Drive Map'!$B$4:$B$33,0)),"Open")))
A8: el-5yr | B8: 1. Eligibility | C8: No owner-builder permit in the last 5 years | D8: Must | E8: This applies to you and to anyone you co-own, or have co-owned, property with. Small second dwellings and further work on the same home are exceptions. The BPC can grant exemptions for special circumstances such as hardship. | F8: G0 | G8: Not started | K8: 01 Eligibility, Land & Planning | L8: =IF(K8="","",IF(IFERROR(INDEX('Google Drive Map'!$G$4:$G$33,MATCH(K8,'Google Drive Map'!$B$4:$B$33,0))&"","")="","",HYPERLINK(INDEX('Google Drive Map'!$G$4:$G$33,MATCH(K8,'Google Drive Map'!$B$4:$B$33,0)),"Open")))
A9: el-elearn | B9: 1. Eligibility | C9: Pass the BPC owner-builder eLearning assessment | D9: Must | E9: Free and online, about 2–3 hours. Download and keep your pass certificate. | F9: G2 | G9: Not started | K9: 01 Eligibility, Land & Planning | L9: =IF(K9="","",IF(IFERROR(INDEX('Google Drive Map'!$G$4:$G$33,MATCH(K9,'Google Drive Map'!$B$4:$B$33,0))&"","")="","",HYPERLINK(INDEX('Google Drive Map'!$G$4:$G$33,MATCH(K9,'Google Drive Map'!$B$4:$B$33,0)),"Open")))
A10: el-white | B10: 1. Eligibility | C10: Complete construction induction training (white card) | D10: Must | E10: It's part of the eligibility criteria. Anyone else working on your site needs one too. | F10: G2 | G10: Not started | K10: 01 Eligibility, Land & Planning | L10: =IF(K10="","",IF(IFERROR(INDEX('Google Drive Map'!$G$4:$G$33,MATCH(K10,'Google Drive Map'!$B$4:$B$33,0))&"","")="","",HYPERLINK(INDEX('Google Drive Map'!$G$4:$G$33,MATCH(K10,'Google Drive Map'!$B$4:$B$33,0)),"Open")))
A11: co-value | B11: 2. Certificate of consent | C11: Estimate the full value of the work | D11: Must | E11: Use market rates for your own labour. Keep the working. The building surveyor and BPC may ask for it. | F11: G2 | G11: Not started | K11: 01 Eligibility, Land & Planning | L11: =IF(K11="","",IF(IFERROR(INDEX('Google Drive Map'!$G$4:$G$33,MATCH(K11,'Google Drive Map'!$B$4:$B$33,0))&"","")="","",HYPERLINK(INDEX('Google Drive Map'!$G$4:$G$33,MATCH(K11,'Google Drive Map'!$B$4:$B$33,0)),"Open")))
A12: co-apply | B12: 2. Certificate of consent | C12: Apply to the BPC with proof of ownership and ID | D12: Must | E12: Include your eLearning pass, construction induction card, title search and project description. There's a non-refundable application fee, so check the BPC fee schedule. | F12: G2 | G12: Not started | K12: 01 Eligibility, Land & Planning | L12: =IF(K12="","",IF(IFERROR(INDEX('Google Drive Map'!$G$4:$G$33,MATCH(K12,'Google Drive Map'!$B$4:$B$33,0))&"","")="","",HYPERLINK(INDEX('Google Drive Map'!$G$4:$G$33,MATCH(K12,'Google Drive Map'!$B$4:$B$33,0)),"Open")))
A13: co-receive | B13: 2. Certificate of consent | C13: Receive your certificate of consent | D13: Must | E13: Give a copy to your relevant building surveyor. It's specific to you, this land and this work. | F13: G2 | G13: Not started | K13: 01 Eligibility, Land & Planning | L13: =IF(K13="","",IF(IFERROR(INDEX('Google Drive Map'!$G$4:$G$33,MATCH(K13,'Google Drive Map'!$B$4:$B$33,0))&"","")="","",HYPERLINK(INDEX('Google Drive Map'!$G$4:$G$33,MATCH(K13,'Google Drive Map'!$B$4:$B$33,0)),"Open")))
A14: de-title | B14: 3. Site, planning & design | C14: Title search: covenants, easements, section 173 agreements | D14: Must | E14: These can limit what, where and how you build. Get the plan of subdivision too. | F14: G0 | G14: Not started | K14: 01 Eligibility, Land & Planning | L14: =IF(K14="","",IF(IFERROR(INDEX('Google Drive Map'!$G$4:$G$33,MATCH(K14,'Google Drive Map'!$B$4:$B$33,0))&"","")="","",HYPERLINK(INDEX('Google Drive Map'!$G$4:$G$33,MATCH(K14,'Google Drive Map'!$B$4:$B$33,0)),"Open")))
A15: de-planning | B15: 3. Site, planning & design | C15: Check zoning & overlays and get a planning permit | D15: If applies | E15: Use VicPlan / Planning Property Report. Heritage, bushfire (BMO), flood, vegetation and neighbourhood character overlays often need a permit from council. | F15: G2 | G15: Not started | K15: 01 Eligibility, Land & Planning | L15: =IF(K15="","",IF(IFERROR(INDEX('Google Drive Map'!$G$4:$G$33,MATCH(K15,'Google Drive Map'!$B$4:$B$33,0))&"","")="","",HYPERLINK(INDEX('Google Drive Map'!$G$4:$G$33,MATCH(K15,'Google Drive Map'!$B$4:$B$33,0)),"Open")))
... A64: mo-tax | B64: 11. Finance & tax | C64: Get tax advice on GST & CGT | D64: Best practice | E64: Building to live in is generally private. Building to sell can be treated as a business. Get advice early. | F64: G0 | G64: Not started | K64: 03 Permits, Insurance & Finance | L64: =IF(K64="","",IF(IFERROR(INDEX('Google Drive Map'!$G$4:$G$33,MATCH(K64,'Google Drive Map'!$B$4:$B$33,0))&"","")="","",HYPERLINK(INDEX('Google Drive Map'!$G$4:$G$33,MATCH(K64,'Google Drive Map'!$B$4:$B$33,0)),"Open")))
L65: =IF(K65="","",IF(IFERROR(INDEX('Google Drive Map'!$G$4:$G$33,MATCH(K65,'Google Drive Map'!$B$4:$B$33,0))&"","")="","",HYPERLINK(INDEX('Google Drive Map'!$G$4:$G$33,MATCH(K65,'Google Drive Map'!$B$4:$B$33,0)),"Open")))
L66: =IF(K66="","",IF(IFERROR(INDEX('Google Drive Map'!$G$4:$G$33,MATCH(K66,'Google Drive Map'!$B$4:$B$33,0))&"","")="","",HYPERLINK(INDEX('Google Drive Map'!$G$4:$G$33,MATCH(K66,'Google Drive Map'!$B$4:$B$33,0)),"Open")))
L67: =IF(K67="","",IF(IFERROR(INDEX('Google Drive Map'!$G$4:$G$33,MATCH(K67,'Google Drive Map'!$B$4:$B$33,0))&"","")="","",HYPERLINK(INDEX('Google Drive Map'!$G$4:$G$33,MATCH(K67,'Google Drive Map'!$B$4:$B$33,0)),"Open")))
L68: =IF(K68="","",IF(IFERROR(INDEX('Google Drive Map'!$G$4:$G$33,MATCH(K68,'Google Drive Map'!$B$4:$B$33,0))&"","")="","",HYPERLINK(INDEX('Google Drive Map'!$G$4:$G$33,MATCH(K68,'Google Drive Map'!$B$4:$B$33,0)),"Open")))
L69: =IF(K69="","",IF(IFERROR(INDEX('Google Drive Map'!$G$4:$G$33,MATCH(K69,'Google Drive Map'!$B$4:$B$33,0))&"","")="","",HYPERLINK(INDEX('Google Drive Map'!$G$4:$G$33,MATCH(K69,'Google Drive Map'!$B$4:$B$33,0)),"Open")))
L70: =IF(K70="","",IF(IFERROR(INDEX('Google Drive Map'!$G$4:$G$33,MATCH(K70,'Google Drive Map'!$B$4:$B$33,0))&"","")="","",HYPERLINK(INDEX('Google Drive Map'!$G$4:$G$33,MATCH(K70,'Google Drive Map'!$B$4:$B$33,0)),"Open")))
L71: =IF(K71="","",IF(IFERROR(INDEX('Google Drive Map'!$G$4:$G$33,MATCH(K71,'Google Drive Map'!$B$4:$B$33,0))&"","")="","",HYPERLINK(INDEX('Google Drive Map'!$G$4:$G$33,MATCH(K71,'Google Drive Map'!$B$4:$B$33,0)),"Open")))
L72: =IF(K72="","",IF(IFERROR(INDEX('Google Drive Map'!$G$4:$G$33,MATCH(K72,'Google Drive Map'!$B$4:$B$33,0))&"","")="","",HYPERLINK(INDEX('Google Drive Map'!$G$4:$G$33,MATCH(K72,'Google Drive Map'!$B$4:$B$33,0)),"Open")))
L73: =IF(K73="","",IF(IFERROR(INDEX('Google Drive Map'!$G$4:$G$33,MATCH(K73,'Google Drive Map'!$B$4:$B$33,0))&"","")="","",HYPERLINK(INDEX('Google Drive Map'!$G$4:$G$33,MATCH(K73,'Google Drive Map'!$B$4:$B$33,0)),"Open")))
L74: =IF(K74="","",IF(IFERROR(INDEX('Google Drive Map'!$G$4:$G$33,MATCH(K74,'Google Drive Map'!$B$4:$B$33,0))&"","")="","",HYPERLINK(INDEX('Google Drive Map'!$G$4:$G$33,MATCH(K74,'Google Drive Map'!$B$4:$B$33,0)),"Open")))
L75: =IF(K75="","",IF(IFERROR(INDEX('Google Drive Map'!$G$4:$G$33,MATCH(K75,'Google Drive Map'!$B$4:$B$33,0))&"","")="","",HYPERLINK(INDEX('Google Drive Map'!$G$4:$G$33,MATCH(K75,'Google Drive Map'!$B$4:$B$33,0)),"Open")))
L76: =IF(K76="","",IF(IFERROR(INDEX('Google Drive Map'!$G$4:$G$33,MATCH(K76,'Google Drive Map'!$B$4:$B$33,0))&"","")="","",HYPERLINK(INDEX('Google Drive Map'!$G$4:$G$33,MATCH(K76,'Google Drive Map'!$B$4:$B$33,0)),"Open")))
... L79: =IF(K79="","",IF(IFERROR(INDEX('Google Drive Map'!$G$4:$G$33,MATCH(K79,'Google Drive Map'!$B$4:$B$33,0))&"","")="","",HYPERLINK(INDEX('Google Drive Map'!$G$4:$G$33,MATCH(K79,'Google Drive Map'!$B$4:$B$33,0)),"Open")))

Sheet Risks
A1: Risk register
A2: Likelihood × impact gives the rating. Review it weekly. Contingency is money set aside for these risks, not for upgrades.
A3: ID | B3: Risk | C3: Likelihood | D3: Impact | E3: Score | F3: Rating | G3: Response | H3: Owner | I3: Status | J3: Next review | K3: Notes
A4: R01 | B4: Site costs blow out (rock, fill, poor soil, services) | C4: Med | D4: High | E4: =IF(OR(C4="",D4=""),"",MATCH(C4,{"Low","Med","High"},0)*MATCH(D4,{"Low","Med","High"},0)) | F4: =IF(E4="","",IF(E4>=6,"High",IF(E4>=3,"Medium","Low"))) | G4: Soil test and feature survey before G1. Get a site-works provisional sum with a cap. | H4: Owner-builder | I4: Open
A5: R02 | B5: Key trade unavailable, program slips | C5: High | D5: Med | E5: =IF(OR(C5="",D5=""),"",MATCH(C5,{"Low","Med","High"},0)*MATCH(D5,{"Low","Med","High"},0)) | F5: =IF(E5="","",IF(E5>=6,"High",IF(E5>=3,"Medium","Low"))) | G5: Book critical-path trades at G3. Keep a backup quote for each. | H5: Owner-builder | I5: Open
A6: R03 | B6: Trade insurance or registration lapses mid-job | C6: Med | D6: High | E6: =IF(OR(C6="",D6=""),"",MATCH(C6,{"Low","Med","High"},0)*MATCH(D6,{"Low","Med","High"},0)) | F6: =IF(E6="","",IF(E6>=6,"High",IF(E6>=3,"Medium","Low"))) | G6: Track expiry dates in the trade register with automatic reminders. | H6: Owner-builder | I6: Open
A7: R04 | B7: Failed inspection | C7: Med | D7: Med | E7: =IF(OR(C7="",D7=""),"",MATCH(C7,{"Low","Med","High"},0)*MATCH(D7,{"Low","Med","High"},0)) | F7: =IF(E7="","",IF(E7>=6,"High",IF(E7>=3,"Medium","Low"))) | G7: Run your own ITP checklist before calling the RBS. | H7: Owner-builder | I7: Open
A8: R05 | B8: Scope creep (upgrades) | C8: High | D8: Med | E8: =IF(OR(C8="",D8=""),"",MATCH(C8,{"Low","Med","High"},0)*MATCH(D8,{"Low","Med","High"},0)) | F8: =IF(E8="","",IF(E8>=6,"High",IF(E8>=3,"Medium","Low"))) | G8: Freeze scope at G1. Every change goes through a written variation. | H8: Owner-builder | I8: Open
A9: R06 | B9: Owner-builder burnout or injury | C9: Med | D9: High | E9: =IF(OR(C9="",D9=""),"",MATCH(C9,{"Low","Med","High"},0)*MATCH(D9,{"Low","Med","High"},0)) | F9: =IF(E9="","",IF(E9>=6,"High",IF(E9>=3,"Medium","Low"))) | G9: Realistic program, personal accident cover, a mentor at each gateway. | H9: Owner-builder | I9: Open
A10: R07 | B10: Wet weather | C10: High | D10: Low | E10: =IF(OR(C10="",D10=""),"",MATCH(C10,{"Low","Med","High"},0)*MATCH(D10,{"Low","Med","High"},0)) | F10: =IF(E10="","",IF(E10>=6,"High",IF(E10>=3,"Medium","Low"))) | G10: Allow weather days in the program. Prioritise lock-up. | H10: Owner-builder | I10: Open
E11: =IF(OR(C11="",D11=""),"",MATCH(C11,{"Low","Med","High"},0)*MATCH(D11,{"Low","Med","High"},0)) | F11: =IF(E11="","",IF(E11>=6,"High",IF(E11>=3,"Medium","Low")))
E12: =IF(OR(C12="",D12=""),"",MATCH(C12,{"Low","Med","High"},0)*MATCH(D12,{"Low","Med","High"},0)) | F12: =IF(E12="","",IF(E12>=6,"High",IF(E12>=3,"Medium","Low")))
E13: =IF(OR(C13="",D13=""),"",MATCH(C13,{"Low","Med","High"},0)*MATCH(D13,{"Low","Med","High"},0)) | F13: =IF(E13="","",IF(E13>=6,"High",IF(E13>=3,"Medium","Low")))
E14: =IF(OR(C14="",D14=""),"",MATCH(C14,{"Low","Med","High"},0)*MATCH(D14,{"Low","Med","High"},0)) | F14: =IF(E14="","",IF(E14>=6,"High",IF(E14>=3,"Medium","Low")))
E15: =IF(OR(C15="",D15=""),"",MATCH(C15,{"Low","Med","High"},0)*MATCH(D15,{"Low","Med","High"},0)) | F15: =IF(E15="","",IF(E15>=6,"High",IF(E15>=3,"Medium","Low")))
E16: =IF(OR(C16="",D16=""),"",MATCH(C16,{"Low","Med","High"},0)*MATCH(D16,{"Low","Med","High"},0)) | F16: =IF(E16="","",IF(E16>=6,"High",IF(E16>=3,"Medium","Low")))
E17: =IF(OR(C17="",D17=""),"",MATCH(C17,{"Low","Med","High"},0)*MATCH(D17,{"Low","Med","High"},0)) | F17: =IF(E17="","",IF(E17>=6,"High",IF(E17>=3,"Medium","Low")))
E18: =IF(OR(C18="",D18=""),"",MATCH(C18,{"Low","Med","High"},0)*MATCH(D18,{"Low","Med","High"},0)) | F18: =IF(E18="","",IF(E18>=6,"High",IF(E18>=3,"Medium","Low")))
E19: =IF(OR(C19="",D19=""),"",MATCH(C19,{"Low","Med","High"},0)*MATCH(D19,{"Low","Med","High"},0)) | F19: =IF(E19="","",IF(E19>=6,"High",IF(E19>=3,"Medium","Low")))
E20: =IF(OR(C20="",D20=""),"",MATCH(C20,{"Low","Med","High"},0)*MATCH(D20,{"Low","Med","High"},0)) | F20: =IF(E20="","",IF(E20>=6,"High",IF(E20>=3,"Medium","Low")))
E21: =IF(OR(C21="",D21=""),"",MATCH(C21,{"Low","Med","High"},0)*MATCH(D21,{"Low","Med","High"},0)) | F21: =IF(E21="","",IF(E21>=6,"High",IF(E21>=3,"Medium","Low")))
